<mujoco>
  <compiler coordinate="local" angle="degree" eulerseq="xyz" />
  <default>
    <geom rgba=".8 .4 .6 1" />
  </default>
  <asset>
    <texture type="skybox" builtin="gradient" rgb1="1 1 1" rgb2=".6 .8 1" width="256" height="256" />
  </asset>
  <worldbody>
    <geom name="floor" pos="0 0 -5" size="10 10 0.125" type="plane" condim="3" rgba="1 1 1 1" />
    <light pos="0 5 5" dir="0 -1 -1" diffuse="1 1 1" />
    <body name="Pelvis" pos="0.0 0.0 0.0" euler="180.0116696150523 30.0000701530499 -180.02333923010465">
      <geom type="box" size="1.55 1.0 0.8500000000000001" />
      <site name="RH_HipZ Extensor Pelvis" pos="2.1056 -0.9983000000000001 0.3217" />
      <site name="LH_HipZ Extensor Pelvis" pos="2.104 1.0017 0.3217" />
      <site name="RH_HipZ Flexor Pelvis" pos="-1.1092 -1.0009000000000001 0.3434" />
      <body name="RH_Femur" pos="0.7105 -1.5900999999999998 1.7895" euler="-70.70299191914359 0.0 0.0">
        <geom type="box" size="0.345 1.79 0.345" />
        <site name="RH_Knee Extensor Femur Mid" pos="0.0452 -2.0257 0.1315" />
        <site name="RH_Knee Flexor Femur" pos="-0.1583 0.5881 -0.40220000000000006" />
        <site name="RH_HipZ Flexor Femur" pos="-0.6624 0.2423 0.0701" />
        <site name="RH_Knee Extensor Femur" pos="-0.3014 0.6724 -0.1609" />
        <site name="RH_Knee Extensor Femur Mid2" pos="-0.6078 -1.7531 0.256" />
        <body name="RH_Tibia" pos="2.1978 -2.2329000000000003 0.1782" euler="0.0 -4.599991658207815 -11.499835906070754">
          <geom type="box" size="2.244 0.27499999999999997 0.27499999999999997" />
          <site name="RH_AnkleZ Extensor Tibia" pos="-1.2661 0.1634 -0.1724" />
          <site name="RH_AnkleZ Extensor Tibia Mid" pos="2.083 0.42069999999999996 -0.1674" />
          <body name="RH_Foot" pos="2.2378 -0.2727 0.0897" euler="-20.000237754631645 0.0 0.0">
            <geom type="box" size="0.31 0.6799999999999999 0.31" />
            <site name="RH_AnkleZ Extensor Foot" pos="0.2167 0.7587 0.0173" />
            <site name="RH_AnkleZ Flexor Foot" pos="0.1939 -0.2013 -0.09940000000000002" />
            <joint name="RH_AnkleZ" pos="0.01 0.27999999999999997 0.02" axis="-0.00020367320369518715 0.9999999792586128 0.0" />
          </body>
          <site name="RH_Knee Flexor Tibia" pos="-1.6477 0.1729 -0.4386" />
          <site name="RH_AnkleZ Flexor Tibia" pos="-1.1594 -0.29650000000000004 -0.0077413" />
          <site name="RH_Knee Extensor Tibia" pos="-1.5982 0.021900000000000003 0.0492" />
          <joint name="RH_Knee" pos="-2.244 0.0 0.0" axis="-0.00020367320369518715 0.0 0.9999999792586128" />
        </body>
        <site name="RH_HipZ Extensor Femur" pos="0.0552 0.7969 0.1961" />
        <joint name="RH_HipZ" pos="0.0 1.79 0.0" axis="-0.00020367320369518715 0.9999999792586128 0.0" />
      </body>
      <body name="LH_Femur" pos="0.7095 1.5899 1.7901" euler="-108.97657263388257 0.0 0.0">
        <geom type="box" size="0.345 1.79 0.345" />
        <site name="LH_Knee Extensor Femur" pos="-0.3025 0.6735 0.1581" />
        <site name="LH_HipZ Extensor Femur" pos="0.0548 0.796 -0.199" />
        <site name="LH_HipZ Flexor Femur" pos="-0.6631 0.2421 -0.07110000000000001" />
        <site name="LH_Knee Flexor Femur" pos="-0.15969999999999998 0.5904 0.4001" />
        <body name="LH_Tibia" pos="2.1975000000000002 -2.2342 -0.1652" euler="0.0 4.599991658207815 -11.499835906070754">
          <geom type="box" size="2.244 0.27499999999999997 0.27499999999999997" />
          <site name="LH_AnkleZ Extensor Tibia" pos="-1.2677 0.16570000000000001 0.1729" />
          <site name="LH_AnkleZ Extensor Tibia Mid" pos="2.0814 0.42300000000000004 0.1767" />
          <site name="LH_Knee Extensor Tibia" pos="-1.5990999999999997 0.0228 -0.049" />
          <site name="LH_AnkleZ Flexor Tibia" pos="-1.1605 -0.29510000000000003 0.0111" />
          <site name="LH_Knee Flexor Tibia" pos="-1.6502 0.1766 0.4379" />
          <body name="LH_Foot" pos="2.2377000000000002 -0.2746 -0.0848" euler="20.000237754631645 0.0 0.0">
            <geom type="box" size="0.31 0.6799999999999999 0.31" />
            <site name="LH_AnkleZ Extensor Foot" pos="0.21480000000000002 0.7645 -0.0136" />
            <site name="LH_AnkleZ Flexor Foot" pos="0.1936 -0.19469999999999998 0.1083" />
            <joint name="LH_AnkleZ" pos="0.01 0.29 -0.01" axis="-0.00020367320369518715 0.9999999792586128 0.0" />
          </body>
          <joint name="LH_Knee" pos="-2.244 0.0 0.0" axis="-0.00020367320369518715 0.0 0.9999999792586128" />
        </body>
        <site name="LH_Knee Extensor Femur mid" pos="0.0443 -2.0263 -0.1186" />
        <site name="LH_Knee Extensor Femur Mid2" pos="-0.6086 -1.7544 -0.2457" />
        <joint name="LH_HipZ" pos="-7.779999999999999e-07 1.79 6.54e-05" axis="-0.00020367320369518715 0.9999999792586128 0.0" />
      </body>
      <site name="LH_HipZ Flexor Pelvis" pos="-1.1108 0.9991 0.3434" />
    </body>
  </worldbody>
</mujoco>