<mujoco>
  <compiler coordinate="local" angle="radian" eulerseq="xyz" />
  <default>
    <geom rgba=".8 .4 .6 1" />
  </default>
  <option collision="predefined" />
  <asset>
    <texture type="skybox" builtin="gradient" rgb1="1 1 1" rgb2=".6 .8 1" width="256" height="256" />
  </asset>
  <worldbody>
    <geom name="floor" pos="0 0 -0.5" size="1 1 0.125" type="plane" condim="3" rgba="1 1 1 1" />
    <light pos="0 5 5" dir="0 -1 -1" diffuse="1 1 1" />
    <body name="Pelvis" pos="0.0 0.0 0.0" euler="3.1417963267948963 0.5236 -3.142">
      <geom type="box" size="0.0155 0.01 0.0085" mass="0.03182" density="3019.0" />
      <site name="RH_HipZ Extensor Pelvis" pos="0.021056 -0.009983 0.003217" size="0.001 0.001 0.001" />
      <site name="LH_HipZ Extensor Pelvis" pos="0.02104 0.010017 0.003217" size="0.001 0.001 0.001" />
      <site name="RH_HipZ Flexor Pelvis" pos="-0.011092 -0.010009 0.003434" size="0.001 0.001 0.001" />
      <body name="RH_Femur" pos="0.007105 -0.015901 0.017895" euler="-1.234 0.0 0.0">
        <geom type="box" size="0.00345 0.0179 0.00345" mass="0.014142" density="8297.0" />
        <site name="RH_Knee Extensor Femur Mid" pos="0.000452 -0.020257 0.001315" size="0.001 0.001 0.001" />
        <site name="RH_Knee Flexor Femur" pos="-0.001583 0.005881 -0.004022" size="0.001 0.001 0.001" />
        <site name="RH_HipZ Flexor Femur" pos="-0.006624 0.002423 0.000701" size="0.001 0.001 0.001" />
        <site name="RH_Knee Extensor Femur" pos="-0.003014 0.006724 -0.001609" size="0.001 0.001 0.001" />
        <site name="RH_Knee Extensor Femur Mid2" pos="-0.006078 -0.017531 0.00256" size="0.001 0.001 0.001" />
        <body name="RH_Tibia" pos="0.021978 -0.022329 0.001782" euler="0.0 -0.080285 -0.20071">
          <geom type="box" size="0.02244 0.00275 0.00275" mass="0.0033380000000000003" density="2459.0" />
          <site name="RH_AnkleZ Extensor Tibia" pos="-0.012661 0.001634 -0.001724" size="0.001 0.001 0.001" />
          <site name="RH_AnkleZ Extensor Tibia Mid" pos="0.02083 0.004207 -0.001674" size="0.001 0.001 0.001" />
          <body name="RH_Foot" pos="0.022378 -0.002727 0.000897" euler="-0.34907 0.0 0.0">
            <geom type="box" size="0.0031 0.0068 0.0031" mass="0.001571" density="3005.0" />
            <site name="RH_AnkleZ Extensor Foot" pos="0.002167 0.007587 0.000173" size="0.001 0.001 0.001" />
            <site name="RH_AnkleZ Flexor Foot" pos="0.001939 -0.002013 -0.000994" size="0.001 0.001 0.001" />
            <joint name="RH_AnkleZ" pos="0.0001 0.0028 0.0002" axis="0 0 1" limited="true" range="-1.39626 0.436332" />
          </body>
          <site name="RH_Knee Flexor Tibia" pos="-0.016477 0.001729 -0.004386" size="0.001 0.001 0.001" />
          <site name="RH_AnkleZ Flexor Tibia" pos="-0.011594 -0.002965 -7.7413e-05" size="0.001 0.001 0.001" />
          <site name="RH_Knee Extensor Tibia" pos="-0.015982 0.000219 0.000492" size="0.001 0.001 0.001" />
          <joint name="RH_Knee" pos="-0.02244 0.0 0.0" axis="0 0 1" limited="true" range="-1.39626 1.0472" />
        </body>
        <site name="RH_HipZ Extensor Femur" pos="0.000552 0.007969 0.001961" size="0.001 0.001 0.001" />
        <joint name="RH_HipZ" pos="0.0 0.0179 0.0" axis="0 0 1" limited="true" range="-1.0472 0.872665" />
      </body>
      <body name="LH_Femur" pos="0.007095 0.015899 0.017901" euler="-1.902 0.0 0.0">
        <geom type="box" size="0.00345 0.0179 0.00345" mass="0.014142" density="8297.0" />
        <site name="LH_Knee Extensor Femur" pos="-0.003025 0.006735 0.001581" size="0.001 0.001 0.001" />
        <site name="LH_HipZ Extensor Femur" pos="0.000548 0.00796 -0.00199" size="0.001 0.001 0.001" />
        <site name="LH_HipZ Flexor Femur" pos="-0.006631 0.002421 -0.000711" size="0.001 0.001 0.001" />
        <site name="LH_Knee Flexor Femur" pos="-0.001597 0.005904 0.004001" size="0.001 0.001 0.001" />
        <body name="LH_Tibia" pos="0.021975 -0.022342 -0.001652" euler="0.0 0.080285 -0.20071">
          <geom type="box" size="0.02244 0.00275 0.00275" mass="0.0033380000000000003" density="2459.0" />
          <site name="LH_AnkleZ Extensor Tibia" pos="-0.012677 0.001657 0.001729" size="0.001 0.001 0.001" />
          <site name="LH_AnkleZ Extensor Tibia Mid" pos="0.020814 0.00423 0.001767" size="0.001 0.001 0.001" />
          <site name="LH_Knee Extensor Tibia" pos="-0.015991 0.000228 -0.00049" size="0.001 0.001 0.001" />
          <site name="LH_AnkleZ Flexor Tibia" pos="-0.011605 -0.002951 0.000111" size="0.001 0.001 0.001" />
          <site name="LH_Knee Flexor Tibia" pos="-0.016502 0.001766 0.004379" size="0.001 0.001 0.001" />
          <body name="LH_Foot" pos="0.022377 -0.002746 -0.000848" euler="0.34907 0.0 0.0">
            <geom type="box" size="0.0031 0.0068 0.0031" mass="0.001571" density="3005.0" />
            <site name="LH_AnkleZ Extensor Foot" pos="0.002148 0.007645 -0.000136" size="0.001 0.001 0.001" />
            <site name="LH_AnkleZ Flexor Foot" pos="0.001936 -0.001947 0.001083" size="0.001 0.001 0.001" />
            <joint name="LH_AnkleZ" pos="0.0001 0.0029 -0.0001" axis="0 0 1" limited="true" range="-1.39626 0.436332" />
          </body>
          <joint name="LH_Knee" pos="-0.02244 0.0 0.0" axis="0 0 1" limited="true" range="-1.39626 1.0472" />
        </body>
        <site name="LH_Knee Extensor Femur mid" pos="0.000443 -0.020263 -0.001186" size="0.001 0.001 0.001" />
        <site name="LH_Knee Extensor Femur Mid2" pos="-0.006086 -0.017544 -0.002457" size="0.001 0.001 0.001" />
        <joint name="LH_HipZ" pos="-7.78e-09 0.0179 6.54e-07" axis="0 0 1" limited="true" range="-1.0472 0.872665" />
      </body>
      <site name="LH_HipZ Flexor Pelvis" pos="-0.011108 0.009991 0.003434" size="0.001 0.001 0.001" />
    </body>
  </worldbody>
  <actuator>
    <muscle name="LH_HipZ-Extmuscle" tendon="LH_HipZ-Exttendon" />
    <muscle name="RH_Knee-Flxmuscle" tendon="RH_Knee-Flxtendon" />
    <muscle name="RH_AnkleZ-Flxmuscle" tendon="RH_AnkleZ-Flxtendon" />
    <muscle name="RH_AnkleZ-Extmuscle" tendon="RH_AnkleZ-Exttendon" />
    <muscle name="RH_Knee-Extmuscle" tendon="RH_Knee-Exttendon" />
    <muscle name="RH_HipZ-Extmuscle" tendon="RH_HipZ-Exttendon" />
    <muscle name="LH_Knee-Extmuscle" tendon="LH_Knee-Exttendon" />
    <muscle name="LH_AnkleZ-Extmuscle" tendon="LH_AnkleZ-Exttendon" />
    <muscle name="LH_AnkleZ-Flxmuscle" tendon="LH_AnkleZ-Flxtendon" />
    <muscle name="LH_Knee-Flxmuscle" tendon="LH_Knee-Flxtendon" />
    <muscle name="LH_HipZ-Flxmuscle" tendon="LH_HipZ-Flxtendon" />
    <muscle name="RH_HipZ-Flxmuscle" tendon="RH_HipZ-Flxtendon" />
  </actuator>
  <tendon>
    <spatial name="LH_HipZ-Exttendon" width="0.001">
      <site site="LH_HipZ Extensor Pelvis" />
      <site site="LH_HipZ Extensor Femur" />
    </spatial>
    <spatial name="RH_Knee-Flxtendon" width="0.001">
      <site site="RH_Knee Flexor Femur" />
      <site site="RH_Knee Flexor Tibia" />
    </spatial>
    <spatial name="RH_AnkleZ-Flxtendon" width="0.001">
      <site site="RH_AnkleZ Flexor Tibia" />
      <site site="RH_AnkleZ Flexor Foot" />
    </spatial>
    <spatial name="RH_AnkleZ-Exttendon" width="0.001">
      <site site="RH_AnkleZ Extensor Tibia" />
      <site site="RH_AnkleZ Extensor Tibia Mid" />
      <site site="RH_AnkleZ Extensor Foot" />
    </spatial>
    <spatial name="RH_Knee-Exttendon" width="0.001">
      <site site="RH_Knee Extensor Femur" />
      <site site="RH_Knee Extensor Femur Mid2" />
      <site site="RH_Knee Extensor Femur Mid" />
      <site site="RH_Knee Extensor Tibia" />
    </spatial>
    <spatial name="RH_HipZ-Exttendon" width="0.001">
      <site site="RH_HipZ Extensor Pelvis" />
      <site site="RH_HipZ Extensor Femur" />
    </spatial>
    <spatial name="LH_Knee-Exttendon" width="0.001">
      <site site="LH_Knee Extensor Femur" />
      <site site="LH_Knee Extensor Femur Mid2" />
      <site site="LH_Knee Extensor Femur mid" />
      <site site="LH_Knee Extensor Tibia" />
    </spatial>
    <spatial name="LH_AnkleZ-Exttendon" width="0.001">
      <site site="LH_AnkleZ Extensor Tibia" />
      <site site="LH_AnkleZ Extensor Tibia Mid" />
      <site site="LH_AnkleZ Extensor Foot" />
    </spatial>
    <spatial name="LH_AnkleZ-Flxtendon" width="0.001">
      <site site="LH_AnkleZ Flexor Tibia" />
      <site site="LH_AnkleZ Flexor Foot" />
    </spatial>
    <spatial name="LH_Knee-Flxtendon" width="0.001">
      <site site="LH_Knee Flexor Femur" />
      <site site="LH_Knee Flexor Tibia" />
    </spatial>
    <spatial name="LH_HipZ-Flxtendon" width="0.001">
      <site site="LH_HipZ Flexor Pelvis" />
      <site site="LH_HipZ Flexor Femur" />
    </spatial>
    <spatial name="RH_HipZ-Flxtendon" width="0.001">
      <site site="RH_HipZ Flexor Pelvis" />
      <site site="RH_HipZ Flexor Femur" />
    </spatial>
  </tendon>
</mujoco>