<mujoco>
  <compiler coordinate="local" angle="radian"/>

  <default>
    <geom rgba=".8 .6 .4 1"/>
  </default>

  <asset>
    <texture type="skybox" builtin="gradient" rgb1="1 1 1" rgb2=".6 .8 1" width="256" height="256"/>
  </asset>

  <worldbody>
    <geom name="floor" pos="0 0 -0.5" size="3 3 0.125" type="plane" condim="3" rgba="1 1 1 1"></geom>
    <light pos="0 1 1" dir="0 -1 -1" diffuse="1 1 1"/>
    <body pos="0 0 0" euler="90.012 -180 30" >
	<geom type="box" size="0.0155 0.0085 0.01"/>
	<body pos="-0.007105 -0.015901 0.017895" euler="-109 0 0">
	    <geom type="box" size="0.00345 0.00345 0.0179"/>
	    <joint type="hinge" pos="0 0 0.0179" axis="0 1 0"/>
	</body>
	</body>
  </worldbody>

  <!--
  <tendon>
    <spatial limited="true" range="0 0.6" width="0.005">
      <site site="end1"/>
      <site site="end2"/>
    </spatial>
  </tendon>
      -->      
</mujoco>

